To : Debian Bug Tracking System <submit@bugs.debian.org>
Subject : Bug#903883: ITP: python-django-dbconn-retry -- reconnect on a failed database
From : Michael Fladischer <fladi@debian.org>
Date : Mon, 16 Jul 2018 08:26:40 +0200
Message-id : 153172240046.9433.7804703343647599070.reportbug@kashyyyk.local
Reply-to : Michael Fladischer <fladi@debian.org>, 903883@bugs.debian.org


Package: wnpp
Severity: wishlist
Owner: Michael Fladischer <fladi@debian.org>
-----BEGIN PGP SIGNED MESSAGE-----
Hash: SHA512
* Package name    : python-django-dbconn-retry
  Version         : 0.1.5
  Upstream Author : Jonas Maurus <jonas-dbconn-retry@gopythongo.com>
* URL             : https://github.com/jdelic/django-dbconn-retry/
* License         : BSD-3-clause
  Programming Lang: Python
  Description     : reconnect on a failed database
 This library monkeypatches django.db.backends.base.BaseDatabaseWrapper so that
 when a database operation fails because the underlying TCP connection was
 already closed, it first tried to reconnect, instead of immediately raising an
 OperationException.
-----BEGIN PGP SIGNATURE-----
iQFFBAEBCgAvFiEEqVSlRXW87UkkCnJc/9PIi5l90WoFAltMOpMRHGZsYWRpQGRl
Ymlhbi5vcmcACgkQ/9PIi5l90WoIHwf/aZ/p6LNMKsCs5WzTxx76czSgkWnbnWwL
lmgAgKNq62KXexBnHqvbmbniM1pDRhcG8u+yCMdIZUU5JHMRvHSQ7W5vC/Nwr8Ns
EW6rwBpIRlUQxW/zouX9kGk7pJ89B8JOsZgaN0hyLgjo5UbhqjPWwwS1STcrlDJJ
84dWH2bO/TMotSNnyrnPWhMb/Q9aNLYtVpowtPmQ/QkFwcK7p2+uNFh3yoNd/5yK
47jqySCuDF4vAMqI5gfUR/WIENd0wD5bRcX475WyyfzWTg2bc09f6iugqO6t6k46
G7MuiCLfPGWfPGfK+FlR4JHKADlncWZTmkTYUSbxA3uoD3Xpez9+fw==
=mVdu
-----END PGP SIGNATURE-----